## 异常

异常处理语句 `try...excpet...finally`

实例代码

```python
import logging

def div(a, b):
    try:
        print(a / b)
    except ZeroDivisionError:
        print("Error: b should not be 0 !!")
    except Exception as e:
        print("Unexpected Error: {}".format(e))
    else:
        print('Run into else only when everything goes well')
    finally:
        print('Always run into finally block.')
# tests
div(2, 0)
div(2, 'bad type')
div(1, 2)

# Mutiple exception in one line
try:
    print(a / b)
except (ZeroDivisionError, TypeError) as e:
    print(e)

# Except block is optional when there is finally
try:
    open(database)
finally:
    close(database)
    
# catch all errors and log it
try:
    do_work()
except:
    # get detail from logging module
    logging.exception('Exception caught!')
    
    # get detail from sys.exc_info() method
    error_type, error_value, trace_back = sys.exc_info()
    print(error_value)
    raise
```

### 总结如下

1. `except`语句可以有多个，Python会按`except`语句的顺序依次匹配你指定的异常，如果异常已经处理就不会再进入后面的`except`语句。
2. `except`语句可以以元组形式同时指定多个异常，参见实例代码。
3. `except`语句后面如果不指定异常类型，则默认捕获所有异常，你可以通过`logging`或者`sys`模块获取当前异常。
4. 如果要捕获异常后要重复抛出，请使用`raise`，后面不要带任何参数或信息。
5. 不建议捕获并抛出同一个异常，请考虑重构你的代码。
6. 不建议在不清楚逻辑的情况下捕获所有异常，有可能你隐藏了很严重的问题。
7. 尽量使用内置的异常处理语句来替换`try/except`语句，比如with语句，`getattr()`方法。

### 抛出异常

如果你需要自主抛出异常一个异常，可以使用`raise`关键字，等同于C#和Java中的`throw`，其语法规则如下。

```python
raise NameError("bad name!")
```

`raise`关键字后面可以指定你要抛出的异常实例，一般来说抛出的异常越详细越好，Python在`exceptions`模块内建了很多的异常类型，通过使用`dir()`函数来查看`exception`s中的异常类型，如下：

```python
import exceptions

print dir(exceptions)
# ['ArithmeticError', 'AssertionError'...]
```

当然你也可以查阅Python的文档库进行更详细的了解。
[Exception hierarchy](https://docs.python.org/2.7/library/exceptions.html#bltin-exceptions)

### 自定义异常类型

Python中自定义自己的异常类型非常简单，只需要要从`Exception`类继承即可(直接或间接)：

```python
class SomeCustomException(Exception):
    pass

class AnotherException(SomeCustomException):
    pass
```

一般你在自定义异常类型时，需要考虑的问题应该是这个异常所应用的场景。如果内置异常已经包括了你需要的异常，建议考虑使用内置的异常类型。

### 传递异常

捕捉到了异常，但是又想重新抛出它（传递异常），使用不带参数的`raise`语句即可：

```python
def f1():
    print(1/0)

def f2():
    try:
        f1()
    except Exception as e:
        raise  # don't raise e !!!

f2()
```

在Python2中，为了保持异常的完整信息，那么你捕获后再次抛出时千万不能在`raise`后面加上异常对象，否则你的`trace`信息就会从此处截断。以上是最简单的重新抛出异常的做法，也是推荐的做法。

还有一些技巧可以考虑，比如抛出异常前你希望对异常的信息进行更新。

```python
def f2():
    try:
        f1()
    except Exception as e:
        e.args += ('more info',)
        raise
```

### Exception 和 BaseException

当我们要捕获一个通用异常时，应该用`Exception`还是`BaseException`？我建议你还是看一下 官方文档说明，这两个异常到底有啥区别呢？ 请看它们之间的继承关系。

```
BaseException
 +-- SystemExit
 +-- KeyboardInterrupt
 +-- GeneratorExit
 +-- Exception
      +-- StopIteration...
      +-- StandardError...
      +-- Warning...
```

从`Exception`的层级结构来看，`BaseException`是最基础的异常类，`Exception`继承了它。`BaseException`除了包含所有的Exception外还包含了`SystemExit`，`KeyboardInterrupt`和`GeneratorExit`三个异常。

由此看来你的程序在捕获所有异常时更应该使用`Exception`而不是`BaseException`，因为被排除的三个异常属于更高级别的异常，合理的做法应该是交给Python的解释器处理。

### 最佳实践

最佳实践不限于编程语言，只是一些规则和填坑后的收获。

1. 只处理你知道的异常，避免捕获所有异常然后吞掉它们。
1. 抛出的异常应该说明原因，有时候你知道异常类型也猜不出所以然。
1. 避免在`catch`语句块中干一些没意义的事情，捕获异常也是需要成本的。
1. 不要使用异常来控制流程，那样你的程序会无比难懂和难维护。
1. 如果有需要，切记使用`finally`来释放资源。
1. 如果有需要，请不要忘记在处理异常后做清理工作或者回滚操作。

## 调试

### 断言

凡是用`print()`来辅助查看的地方，都可以用断言（assert）来替代：

```python
def foo(s):
    n = int(s)
    assert n != 0, 'n is zero!'
    return 10 / n

def main():
    foo('0')
```

`assert`的意思是，表达式`n != 0`应该是`True`，否则，根据程序运行的逻辑，后面的代码肯定会出错。

如果断言失败，`assert`语句本身就会抛出`AssertionError`：

```shell
$ python err.py
Traceback (most recent call last):
  ...
AssertionError: n is zero!
```

启动Python解释器时可以用`-O`参数来关闭`assert`：

```shell
$ python -O err.py
Traceback (most recent call last):
  ...
ZeroDivisionError: division by zero
```

> 注意：断言的开关“-O”是英文大写字母O，不是数字0。

关闭后，你可以把所有的`assert`语句当成`pass`来看。

### logging

和`assert`比，`logging`不会抛出错误，而且可以输出到文件：

```python
import logging
logging.basicConfig(level=logging.INFO)

s = '0'
n = int(s)
logging.info('n = %d' % n)
print(10 / n)
```

输出：

```shell
INFO:root:n = 0
Traceback (most recent call last):
  File "err.py", line 8, in <module>
    print(10 / n)
ZeroDivisionError: division by zero
```

这就是`logging`的好处，它允许你指定记录信息的级别，有`debug`，`info`，`warning`，`error`等几个级别，当我们指定`level=INFO`时，`logging.debug`就不起作用了。同理，指定`level=WARNING`后，`debug`和`info`就不起作用了。这样一来，你可以放心地输出不同级别的信息，也不用删除，最后统一控制输出哪个级别的信息。

`logging`的另一个好处是通过简单的配置，一条语句可以同时输出到不同的地方，比如console和文件。

## 单元测试

如果你听说过“测试驱动开发”（TDD：Test-Driven Development），单元测试就不陌生。

单元测试是用来对一个模块、一个函数或者一个类来进行正确性检验的测试工作。

比如对函数`abs()`，我们可以编写出以下几个测试用例：

1. 输入正数，比如`1`、`1.2`、`0.99`，期待返回值与输入相同；
2. 输入负数，比如`-1`、`-1.2`、`-0.99`，期待返回值与输入相反；
3. 输入`0`，期待返回`0`；
4. 输入非数值类型，比如`None`、`[]`、`{}`，期待抛出`TypeError`。

把上面的测试用例放到一个测试模块里，就是一个完整的单元测试。

单元测试通过后有什么意义呢？如果我们对`abs()`函数代码做了修改，只需要再跑一遍单元测试，如果通过，说明我们的修改不会对`abs()`函数原有的行为造成影响，如果测试不通过，说明我们的修改与原有行为不一致，要么修改代码，要么修改测试。

### 编写单元测试

首先编写一个`Dict`类，这个类的行为和`dict`一致，但是可以通过属性来访问，用起来就像下面这样：

```python
>>> d = Dict(a=1, b=2)
>>> d['a']
1
>>> d.a
1
```

`mydict.py`代码如下：

```python
class Dict(dict):

    def __init__(self, **kw):
        super().__init__(**kw)

    def __getattr__(self, key):
        try:
            return self[key]
        except KeyError:
            raise AttributeError(r"'Dict' object has no attribute '%s'" % key)

    def __setattr__(self, key, value):
        self[key] = value
```

为了编写单元测试，我们需要引入Python自带的`unittest`模块，编写`mydict_test.py`如下：

```python
import unittest

from mydict import Dict

class TestDict(unittest.TestCase):

    def test_init(self):
        d = Dict(a=1, b='test')
        self.assertEqual(d.a, 1)
        self.assertEqual(d.b, 'test')
        self.assertTrue(isinstance(d, dict))

    def test_key(self):
        d = Dict()
        d['key'] = 'value'
        self.assertEqual(d.key, 'value')

    def test_attr(self):
        d = Dict()
        d.key = 'value'
        self.assertTrue('key' in d)
        self.assertEqual(d['key'], 'value')

    def test_keyerror(self):
        d = Dict()
        with self.assertRaises(KeyError):
            value = d['empty']

    def test_attrerror(self):
        d = Dict()
        with self.assertRaises(AttributeError):
            value = d.empty
```

编写单元测试时，我们需要编写一个测试类，从`unittest.TestCase`继承。

以`test`开头的方法就是测试方法，不以`test`开头的方法不被认为是测试方法，测试的时候不会被执行。

由于`unittest.TestCase`提供了很多内置的条件判断，我们只需要调用这些方法就可以断言输出是否是我们所期望的。最常用的断言就是`assertEqual()`：

```python
self.assertEqual(abs(-1), 1)  # 断言函数返回的结果与1相等
```

另一种重要的断言就是期待抛出指定类型的Error，比如通过`d['empty']`访问不存在的key时，断言会抛出`KeyError`：

```python
with self.assertRaises(KeyError):
    value = d['empty']
```

而通过`d.empty`访问不存在的key时，我们期待抛出`AttributeError`：

```python
with self.assertRaises(AttributeError):
    value = d.empty
```

### 运行单元测试

一旦编写好单元测试，我们就可以运行单元测试。最简单的运行方式是在`mydict_test.py`的最后加上两行代码：

```python
if __name__ == '__main__':
    unittest.main()
```

这样就可以把`mydict_test.py`当做正常的python脚本运行：

```shell
$ python mydict_test.py
```

另一种方法是在命令行通过参数`-m unittest`直接运行单元测试：

```shell
$ python -m unittest mydict_test
.....
----------------------------------------------------------------------
Ran 5 tests in 0.000s

OK
```

这是推荐的做法，因为这样可以一次批量运行很多单元测试，并且，有很多工具可以自动来运行这些单元测试。

### setUp与tearDown

可以在单元测试中编写两个特殊的`setUp()`和`tearDown()`方法。这两个方法会分别在每调用一个测试方法的前后分别被执行。

`setUp()`和`tearDown()`方法有什么用呢？设想你的测试需要启动一个数据库，这时，就可以在`setUp()`方法中连接数据库，在`tearDown()`方法中关闭数据库，这样，不必在每个测试方法中重复相同的代码：

```python
class TestDict(unittest.TestCase):

    def setUp(self):
        print('setUp...')

    def tearDown(self):
        print('tearDown...')
```

可以再次运行测试看看每个测试方法调用前后是否会打印出`setUp...`和`tearDown...`。

## 文档测试

当我们编写注释时，如果写上这样的注释：

```python
def abs(n):
    '''
    Function to get absolute value of number.
    
    Example:
    
    >>> abs(1)
    1
    >>> abs(-1)
    1
    >>> abs(0)
    0
    '''
    return n if n >= 0 else (-n)
```

无疑更明确地告诉函数的调用者该函数的期望输入和输出。

并且，Python内置的“文档测试”（doctest）模块可以直接提取注释中的代码并执行测试。

doctest严格按照Python交互式命令行的输入和输出来判断测试结果是否正确。只有测试异常的时候，可以用`...`表示中间一大段烦人的输出。

让我们用doctest来测试上次编写的`Dict`类：

```python
# mydict2.py
class Dict(dict):
    '''
    Simple dict but also support access as x.y style.

    >>> d1 = Dict()
    >>> d1['x'] = 100
    >>> d1.x
    100
    >>> d1.y = 200
    >>> d1['y']
    200
    >>> d2 = Dict(a=1, b=2, c='3')
    >>> d2.c
    '3'
    >>> d2['empty']
    Traceback (most recent call last):
        ...
    KeyError: 'empty'
    >>> d2.empty
    Traceback (most recent call last):
        ...
    AttributeError: 'Dict' object has no attribute 'empty'
    '''
    def __init__(self, **kw):
        super(Dict, self).__init__(**kw)

    def __getattr__(self, key):
        try:
            return self[key]
        except KeyError:
            raise AttributeError(r"'Dict' object has no attribute '%s'" % key)

    def __setattr__(self, key, value):
        self[key] = value

if __name__=='__main__':
    import doctest
    doctest.testmod()
```

运行`python mydict2.py`：

```shell
$ python mydict2.py
```

什么输出也没有。这说明我们编写的doctest运行都是正确的。如果程序有问题，比如把`__getattr__()`方法注释掉，再运行就会报错：

```shell
$ python mydict2.py
**********************************************************************
File "/Users/michael/Github/learn-python3/samples/debug/mydict2.py", line 10, in __main__.Dict
Failed example:
    d1.x
Exception raised:
    Traceback (most recent call last):
      ...
    AttributeError: 'Dict' object has no attribute 'x'
**********************************************************************
File "/Users/michael/Github/learn-python3/samples/debug/mydict2.py", line 16, in __main__.Dict
Failed example:
    d2.c
Exception raised:
    Traceback (most recent call last):
      ...
    AttributeError: 'Dict' object has no attribute 'c'
**********************************************************************
1 items had failures:
   2 of   9 in __main__.Dict
***Test Failed*** 2 failures.
```

注意到最后3行代码。当模块正常导入时，doctest不会被执行。只有在命令行直接运行时，才执行doctest。所以，不必担心doctest会在非测试环境下执行。